Workbook

Sheet START HERE
A1: LSC UPDATE SYSTEM — SAFE TEST
A2: Purpose | B2: Test Excel → export → GitHub → test website
A3: Rule | B3: Only type real match/fixture facts in Updates.
A4: 1 | B4: Known next defence | C4: Add a new row. If unknown, do nothing: TBD is standard.
A5: 2 | B5: Match completed | C5: Change Status to Completed; enter Result Type and Score.
A6: 3 | B6: Successful defence | C6: Use Holder win, or Draw / tie where appropriate.
A7: 4 | B7: Transfer | C7: Use Challenger win.
A8: 5 | B8: Do not edit | C8: Grey calculated columns.
A9: Dates | B9: Multi-day matches | C9: Use Fixture Date for the start date and Fixture End Date for the final day. Leave End Date blank for one-day matches.

Sheet Baseline
A1: Championship | B1: Sport | C1: Competition | D1: Baseline Holder | E1: Baseline Since | F1: Current Defences | G1: Transfers | H1: Total Defences
A2: Charles Bannerman Belt | B2: Cricket | C2: Men's Test | D2: South Africa | E2: 45953 | F2: 2 | G2: 214 | H2: 404
A3: Myrtle Maclagan Medal | B3: Cricket | C3: Women's Test | D3: Australia | E3: 46089 | F3: 0 | G3: 8 | H3: 74
A4: John Edrich Jug | B4: Cricket | C4: Men's ODI | D4: Australia | E4: 46187 | F4: 0 | G4: 358 | H4: 596
A5: Tina Macpherson Trophy | B5: Cricket | C5: Women's ODI | D5: Australia | E5: 46077 | F5: 5 | G5: 120 | H5: 251
A6: Ricky Ponting Ribbon | B6: Cricket | C6: Men's T20I | D6: Ireland | E6: 46199 | F6: 1 | G6: 89 | H6: 152
A7: Rebecca Rolls Ribbon | B7: Cricket | C7: Women's T20I | D7: Australia | E7: 46186 | F7: 6 | G7: 76 | H7: 139
A8: Yusuf Pathan Plate | B8: Cricket | C8: IPL | D8: Royal Challengers Bengaluru | E8: 46173 | F8: 0 | G8: 150 | H8: 125
A9: Uwe Seeler Trophy | B9: Football | C9: Bundesliga | D9: Bayern München | E9: 46081 | F9: 10 | G9: 681 | H9: 1442
A10: Heidi Mohr Pott | B10: Football | C10: Frauen-Bundesliga | D10: Bayern München | E10: 45730 | F10: 32 | G10: 113 | H10: 655

Sheet Lists
A1: Championship | B1: Code | D1: Status | E1: Result Type
A2: Charles Bannerman Belt | B2: CBB | D2: Scheduled | E2: Holder win
A3: Myrtle Maclagan Medal | B3: MMM | D3: Awaiting result | E3: Challenger win
A4: John Edrich Jug | B4: JEJ | D4: Completed | E4: Draw / tie
A5: Tina Macpherson Trophy | B5: TMT | D5: Postponed | E5: No result
A6: Ricky Ponting Ribbon | B6: RPR | D6: Cancelled
A7: Rebecca Rolls Ribbon | B7: RRR
A8: Yusuf Pathan Plate | B8: YPP
A9: Uwe Seeler Trophy | B9: UST
A10: Heidi Mohr Pott | B10: HMP

Sheet Updates
A1: Event ID (auto) | B1: Championship | C1: Fixture Date | D1: Opponent | E1: Venue | F1: Status | G1: Result Type | H1: Result / Score | I1: Source URL | J1: Holder Before | K1: Outcome | L1: Holder After | M1: Reign Since After | N1: Current Defences After | O1: Transfers After | P1: Total Defences After | Q1: Notes | R1: Fixture End Date (optional)
A2: =IF(OR(B2="",C2=""),"",VLOOKUP(B2,Lists!$A$2:$B$10,2,FALSE)&"-"&TEXT(C2,"yyyymmdd")&"-01") -> CBB-20261009-01 | B2: Charles Bannerman Belt | C2: 46304 | D2: Australia | E2: Kingsmead · Durban | F2: Completed | G2: Challenger win | H2: Australia win by 214 runs | J2: =IF(B2="","",VLOOKUP(B2,Baseline!$A$2:$H$10,4,FALSE)) -> South Africa | K2: =IF(B2="","",IF(F2<>"Completed",F2,IF(G2="Challenger win","Transfer",IF(OR(G2="Holder win",G2="Draw / tie"),"Defence",IF(G2="No result","No result","INVALID — CHECK RESULT TYPE"))))) -> Transfer | L2: =IF(B2="","",IF(K2="INVALID — CHECK RESULT TYPE","",IF(K2="Transfer",D2,J2))) -> Australia | M2: =IF(B2="","",IF(K2="INVALID — CHECK RESULT TYPE","",IF(K2="Transfer",IF(R2<>"",R2,C2),VLOOKUP(B2,Baseline!$A$2:$H$10,5,FALSE)))) -> 46308 | N2: =IF(B2="","",IF(K2="INVALID — CHECK RESULT TYPE","",IF(K2="Transfer",0,VLOOKUP(B2,Baseline!$A$2:$H$10,6,FALSE)+IF(K2="Defence",1,0)))) -> 0 | O2: =IF(B2="","",IF(K2="INVALID — CHECK RESULT TYPE","",VLOOKUP(B2,Baseline!$A$2:$H$10,7,FALSE)+IF(K2="Transfer",1,0))) -> 215 | P2: =IF(B2="","",IF(K2="INVALID — CHECK RESULT TYPE","",VLOOKUP(B2,Baseline!$A$2:$H$10,8,FALSE)+IF(K2="Defence",1,0))) -> 404 | R2: 46308
A3: =IF(OR(B3="",C3=""),"",VLOOKUP(B3,Lists!$A$2:$B$10,2,FALSE)&"-"&TEXT(C3,"yyyymmdd")&"-"&TEXT(COUNTIFS($B$2:B3,B3,$C$2:C3,C3),"00")) -> MMM-20270408-01 | B3: Myrtle Maclagan Medal | C3: 46485 | D3: South Africa | E3: JB Marks Oval · Potchefstroom | F3: Scheduled | J3: =IF(B3="","",IFERROR(LOOKUP(2,1/($B$2:B2=B3),$L$2:L2),VLOOKUP(B3,Baseline!$A$2:$H$10,4,FALSE))) -> Australia | K3: =IF(B3="","",IF(F3<>"Completed",F3,IF(G3="Challenger win","Transfer",IF(OR(G3="Holder win",G3="Draw / tie"),"Defence",IF(G3="No result","No result","INVALID — CHECK RESULT TYPE"))))) -> Scheduled | L3: =IF(B3="","",IF(K3="INVALID — CHECK RESULT TYPE","",IF(K3="Transfer",D3,J3))) -> Australia | M3: =IF(B3="","",IF(K3="INVALID — CHECK RESULT TYPE","",IF(K3="Transfer",IF(R3<>"",R3,C3),IFERROR(LOOKUP(2,1/($B$2:B2=B3),$M$2:M2),VLOOKUP(B3,Baseline!$A$2:$H$10,5,FALSE))))) -> 46089 | N3: =IF(B3="","",IF(K3="INVALID — CHECK RESULT TYPE","",IF(K3="Transfer",0,IFERROR(LOOKUP(2,1/($B$2:B2=B3),$N$2:N2),VLOOKUP(B3,Baseline!$A$2:$H$10,6,FALSE))+IF(K3="Defence",1,0)))) -> 0 | O3: =IF(B3="","",IF(K3="INVALID — CHECK RESULT TYPE","",IFERROR(LOOKUP(2,1/($B$2:B2=B3),$O$2:O2),VLOOKUP(B3,Baseline!$A$2:$H$10,7,FALSE))+IF(K3="Transfer",1,0))) -> 8 | P3: =IF(B3="","",IF(K3="INVALID — CHECK RESULT TYPE","",IFERROR(LOOKUP(2,1/($B$2:B2=B3),$P$2:P2),VLOOKUP(B3,Baseline!$A$2:$H$10,8,FALSE))+IF(K3="Defence",1,0))) -> 74 | R3: 46488
A4: =IF(OR(B4="",C4=""),"",VLOOKUP(B4,Lists!$A$2:$B$10,2,FALSE)&"-"&TEXT(C4,"yyyymmdd")&"-"&TEXT(COUNTIFS($B$2:B4,B4,$C$2:C4,C4),"00")) -> JEJ-20260915-01 | B4: John Edrich Jug | C4: 46280 | D4: Zimbabwe | E4: Harare Sports Club · Harare | F4: Completed | G4: Holder win | H4: def Zimbabwe by 59 runs | J4: =IF(B4="","",IFERROR(LOOKUP(2,1/($B$2:B3=B4),$L$2:L3),VLOOKUP(B4,Baseline!$A$2:$H$10,4,FALSE))) -> Australia | K4: =IF(B4="","",IF(F4<>"Completed",F4,IF(G4="Challenger win","Transfer",IF(OR(G4="Holder win",G4="Draw / tie"),"Defence",IF(G4="No result","No result","INVALID — CHECK RESULT TYPE"))))) -> Defence | L4: =IF(B4="","",IF(K4="INVALID — CHECK RESULT TYPE","",IF(K4="Transfer",D4,J4))) -> Australia | M4: =IF(B4="","",IF(K4="INVALID — CHECK RESULT TYPE","",IF(K4="Transfer",IF(R4<>"",R4,C4),IFERROR(LOOKUP(2,1/($B$2:B3=B4),$M$2:M3),VLOOKUP(B4,Baseline!$A$2:$H$10,5,FALSE))))) -> 46187 | N4: =IF(B4="","",IF(K4="INVALID — CHECK RESULT TYPE","",IF(K4="Transfer",0,IFERROR(LOOKUP(2,1/($B$2:B3=B4),$N$2:N3),VLOOKUP(B4,Baseline!$A$2:$H$10,6,FALSE))+IF(K4="Defence",1,0)))) -> 1 | O4: =IF(B4="","",IF(K4="INVALID — CHECK RESULT TYPE","",IFERROR(LOOKUP(2,1/($B$2:B3=B4),$O$2:O3),VLOOKUP(B4,Baseline!$A$2:$H$10,7,FALSE))+IF(K4="Transfer",1,0))) -> 358 | P4: =IF(B4="","",IF(K4="INVALID — CHECK RESULT TYPE","",IFERROR(LOOKUP(2,1/($B$2:B3=B4),$P$2:P3),VLOOKUP(B4,Baseline!$A$2:$H$10,8,FALSE))+IF(K4="Defence",1,0))) -> 597
A5: =IF(OR(B5="",C5=""),"",VLOOKUP(B5,Lists!$A$2:$B$10,2,FALSE)&"-"&TEXT(C5,"yyyymmdd")&"-"&TEXT(COUNTIFS($B$2:B5,B5,$C$2:C5,C5),"00")) -> TMT-20261009-01 | B5: Tina Macpherson Trophy | C5: 46304 | D5: Bangladesh | E5: Allan Border Field · Brisbane | F5: Completed | G5: Holder win | H5: def Bangladesh by 7 Wickets | J5: =IF(B5="","",IFERROR(LOOKUP(2,1/($B$2:B4=B5),$L$2:L4),VLOOKUP(B5,Baseline!$A$2:$H$10,4,FALSE))) -> Australia | K5: =IF(B5="","",IF(F5<>"Completed",F5,IF(G5="Challenger win","Transfer",IF(OR(G5="Holder win",G5="Draw / tie"),"Defence",IF(G5="No result","No result","INVALID — CHECK RESULT TYPE"))))) -> Defence | L5: =IF(B5="","",IF(K5="INVALID — CHECK RESULT TYPE","",IF(K5="Transfer",D5,J5))) -> Australia | M5: =IF(B5="","",IF(K5="INVALID — CHECK RESULT TYPE","",IF(K5="Transfer",IF(R5<>"",R5,C5),IFERROR(LOOKUP(2,1/($B$2:B4=B5),$M$2:M4),VLOOKUP(B5,Baseline!$A$2:$H$10,5,FALSE))))) -> 46077 | N5: =IF(B5="","",IF(K5="INVALID — CHECK RESULT TYPE","",IF(K5="Transfer",0,IFERROR(LOOKUP(2,1/($B$2:B4=B5),$N$2:N4),VLOOKUP(B5,Baseline!$A$2:$H$10,6,FALSE))+IF(K5="Defence",1,0)))) -> 6 | O5: =IF(B5="","",IF(K5="INVALID — CHECK RESULT TYPE","",IFERROR(LOOKUP(2,1/($B$2:B4=B5),$O$2:O4),VLOOKUP(B5,Baseline!$A$2:$H$10,7,FALSE))+IF(K5="Transfer",1,0))) -> 120 | P5: =IF(B5="","",IF(K5="INVALID — CHECK RESULT TYPE","",IFERROR(LOOKUP(2,1/($B$2:B4=B5),$P$2:P4),VLOOKUP(B5,Baseline!$A$2:$H$10,8,FALSE))+IF(K5="Defence",1,0))) -> 252
A6: =IF(OR(B6="",C6=""),"",VLOOKUP(B6,Lists!$A$2:$B$10,2,FALSE)&"-"&TEXT(C6,"yyyymmdd")&"-"&TEXT(COUNTIFS($B$2:B6,B6,$C$2:C6,C6),"00")) -> RRR-20261018-01 | B6: Rebecca Rolls Ribbon | C6: 46313 | D6: New Zealand | E6: North Sydney Oval · Sydney | F6: Scheduled | J6: =IF(B6="","",IFERROR(LOOKUP(2,1/($B$2:B5=B6),$L$2:L5),VLOOKUP(B6,Baseline!$A$2:$H$10,4,FALSE))) -> Australia | K6: =IF(B6="","",IF(F6<>"Completed",F6,IF(G6="Challenger win","Transfer",IF(OR(G6="Holder win",G6="Draw / tie"),"Defence",IF(G6="No result","No result","INVALID — CHECK RESULT TYPE"))))) -> Scheduled | L6: =IF(B6="","",IF(K6="INVALID — CHECK RESULT TYPE","",IF(K6="Transfer",D6,J6))) -> Australia | M6: =IF(B6="","",IF(K6="INVALID — CHECK RESULT TYPE","",IF(K6="Transfer",IF(R6<>"",R6,C6),IFERROR(LOOKUP(2,1/($B$2:B5=B6),$M$2:M5),VLOOKUP(B6,Baseline!$A$2:$H$10,5,FALSE))))) -> 46186 | N6: =IF(B6="","",IF(K6="INVALID — CHECK RESULT TYPE","",IF(K6="Transfer",0,IFERROR(LOOKUP(2,1/($B$2:B5=B6),$N$2:N5),VLOOKUP(B6,Baseline!$A$2:$H$10,6,FALSE))+IF(K6="Defence",1,0)))) -> 6 | O6: =IF(B6="","",IF(K6="INVALID — CHECK RESULT TYPE","",IFERROR(LOOKUP(2,1/($B$2:B5=B6),$O$2:O5),VLOOKUP(B6,Baseline!$A$2:$H$10,7,FALSE))+IF(K6="Transfer",1,0))) -> 76 | P6: =IF(B6="","",IF(K6="INVALID — CHECK RESULT TYPE","",IFERROR(LOOKUP(2,1/($B$2:B5=B6),$P$2:P5),VLOOKUP(B6,Baseline!$A$2:$H$10,8,FALSE))+IF(K6="Defence",1,0))) -> 139
A7: =IF(OR(B7="",C7=""),"",VLOOKUP(B7,Lists!$A$2:$B$10,2,FALSE)&"-"&TEXT(C7,"yyyymmdd")&"-"&TEXT(COUNTIFS($B$2:B7,B7,$C$2:C7,C7),"00")) -> UST-20260828-01 | B7: Uwe Seeler Trophy | C7: 46262 | D7: VfB Stuttgart | F7: Completed | G7: Holder win | H7: Bayern München 5 - VfB Stuttgart 1 | J7: =IF(B7="","",IFERROR(LOOKUP(2,1/($B$2:B6=B7),$L$2:L6),VLOOKUP(B7,Baseline!$A$2:$H$10,4,FALSE))) -> Bayern München | K7: =IF(B7="","",IF(F7<>"Completed",F7,IF(G7="Challenger win","Transfer",IF(OR(G7="Holder win",G7="Draw / tie"),"Defence",IF(G7="No result","No result","INVALID — CHECK RESULT TYPE"))))) -> Defence | L7: =IF(B7="","",IF(K7="INVALID — CHECK RESULT TYPE","",IF(K7="Transfer",D7,J7))) -> Bayern München | M7: =IF(B7="","",IF(K7="INVALID — CHECK RESULT TYPE","",IF(K7="Transfer",IF(R7<>"",R7,C7),IFERROR(LOOKUP(2,1/($B$2:B6=B7),$M$2:M6),VLOOKUP(B7,Baseline!$A$2:$H$10,5,FALSE))))) -> 46081 | N7: =IF(B7="","",IF(K7="INVALID — CHECK RESULT TYPE","",IF(K7="Transfer",0,IFERROR(LOOKUP(2,1/($B$2:B6=B7),$N$2:N6),VLOOKUP(B7,Baseline!$A$2:$H$10,6,FALSE))+IF(K7="Defence",1,0)))) -> 11 | O7: =IF(B7="","",IF(K7="INVALID — CHECK RESULT TYPE","",IFERROR(LOOKUP(2,1/($B$2:B6=B7),$O$2:O6),VLOOKUP(B7,Baseline!$A$2:$H$10,7,FALSE))+IF(K7="Transfer",1,0))) -> 681 | P7: =IF(B7="","",IF(K7="INVALID — CHECK RESULT TYPE","",IFERROR(LOOKUP(2,1/($B$2:B6=B7),$P$2:P6),VLOOKUP(B7,Baseline!$A$2:$H$10,8,FALSE))+IF(K7="Defence",1,0))) -> 1443
A8: =IF(OR(B8="",C8=""),"",VLOOKUP(B8,Lists!$A$2:$B$10,2,FALSE)&"-"&TEXT(C8,"yyyymmdd")&"-"&TEXT(COUNTIFS($B$2:B8,B8,$C$2:C8,C8),"00")) -> HMP-20260831-01 | B8: Heidi Mohr Pott | C8: 46265 | D8: 1. FSV Mainz 05 | F8: Scheduled | J8: =IF(B8="","",IFERROR(LOOKUP(2,1/($B$2:B7=B8),$L$2:L7),VLOOKUP(B8,Baseline!$A$2:$H$10,4,FALSE))) -> Bayern München | K8: =IF(B8="","",IF(F8<>"Completed",F8,IF(G8="Challenger win","Transfer",IF(OR(G8="Holder win",G8="Draw / tie"),"Defence",IF(G8="No result","No result","INVALID — CHECK RESULT TYPE"))))) -> Scheduled | L8: =IF(B8="","",IF(K8="INVALID — CHECK RESULT TYPE","",IF(K8="Transfer",D8,J8))) -> Bayern München | M8: =IF(B8="","",IF(K8="INVALID — CHECK RESULT TYPE","",IF(K8="Transfer",IF(R8<>"",R8,C8),IFERROR(LOOKUP(2,1/($B$2:B7=B8),$M$2:M7),VLOOKUP(B8,Baseline!$A$2:$H$10,5,FALSE))))) -> 45730 | N8: =IF(B8="","",IF(K8="INVALID — CHECK RESULT TYPE","",IF(K8="Transfer",0,IFERROR(LOOKUP(2,1/($B$2:B7=B8),$N$2:N7),VLOOKUP(B8,Baseline!$A$2:$H$10,6,FALSE))+IF(K8="Defence",1,0)))) -> 32 | O8: =IF(B8="","",IF(K8="INVALID — CHECK RESULT TYPE","",IFERROR(LOOKUP(2,1/($B$2:B7=B8),$O$2:O7),VLOOKUP(B8,Baseline!$A$2:$H$10,7,FALSE))+IF(K8="Transfer",1,0))) -> 113 | P8: =IF(B8="","",IF(K8="INVALID — CHECK RESULT TYPE","",IFERROR(LOOKUP(2,1/($B$2:B7=B8),$P$2:P7),VLOOKUP(B8,Baseline!$A$2:$H$10,8,FALSE))+IF(K8="Defence",1,0))) -> 655
A9: =IF(OR(B9="",C9=""),"",VLOOKUP(B9,Lists!$A$2:$B$10,2,FALSE)&"-"&TEXT(C9,"yyyymmdd")&"-"&TEXT(COUNTIFS($B$2:B9,B9,$C$2:C9,C9),"00")) -> UST-20260904-01 | B9: Uwe Seeler Trophy | C9: 46269 | D9: Schalke FC | F9: Scheduled | J9: =IF(B9="","",IFERROR(LOOKUP(2,1/($B$2:B8=B9),$L$2:L8),VLOOKUP(B9,Baseline!$A$2:$H$10,4,FALSE))) -> Bayern München | K9: =IF(B9="","",IF(F9<>"Completed",F9,IF(G9="Challenger win","Transfer",IF(OR(G9="Holder win",G9="Draw / tie"),"Defence",IF(G9="No result","No result","INVALID — CHECK RESULT TYPE"))))) -> Scheduled | L9: =IF(B9="","",IF(K9="INVALID — CHECK RESULT TYPE","",IF(K9="Transfer",D9,J9))) -> Bayern München | M9: =IF(B9="","",IF(K9="INVALID — CHECK RESULT TYPE","",IF(K9="Transfer",IF(R9<>"",R9,C9),IFERROR(LOOKUP(2,1/($B$2:B8=B9),$M$2:M8),VLOOKUP(B9,Baseline!$A$2:$H$10,5,FALSE))))) -> 46081 | N9: =IF(B9="","",IF(K9="INVALID — CHECK RESULT TYPE","",IF(K9="Transfer",0,IFERROR(LOOKUP(2,1/($B$2:B8=B9),$N$2:N8),VLOOKUP(B9,Baseline!$A$2:$H$10,6,FALSE))+IF(K9="Defence",1,0)))) -> 11 | O9: =IF(B9="","",IF(K9="INVALID — CHECK RESULT TYPE","",IFERROR(LOOKUP(2,1/($B$2:B8=B9),$O$2:O8),VLOOKUP(B9,Baseline!$A$2:$H$10,7,FALSE))+IF(K9="Transfer",1,0))) -> 681 | P9: =IF(B9="","",IF(K9="INVALID — CHECK RESULT TYPE","",IFERROR(LOOKUP(2,1/($B$2:B8=B9),$P$2:P8),VLOOKUP(B9,Baseline!$A$2:$H$10,8,FALSE))+IF(K9="Defence",1,0))) -> 1443
A10: =IF(OR(B10="",C10=""),"",VLOOKUP(B10,Lists!$A$2:$B$10,2,FALSE)&"-"&TEXT(C10,"yyyymmdd")&"-"&TEXT(COUNTIFS($B$2:B10,B10,$C$2:C10,C10),"00")) -> JEJ-20260918-01 | B10: John Edrich Jug | C10: 46283 | D10: Zimbabwe | E10: Harare Sports Club · Harare | F10: Completed | G10: Holder win | H10: def Zimbabwe by 84 runs | J10: =IF(B10="","",IFERROR(LOOKUP(2,1/($B$2:B9=B10),$L$2:L9),VLOOKUP(B10,Baseline!$A$2:$H$10,4,FALSE))) -> Australia | K10: =IF(B10="","",IF(F10<>"Completed",F10,IF(G10="Challenger win","Transfer",IF(OR(G10="Holder win",G10="Draw / tie"),"Defence",IF(G10="No result","No result","INVALID — CHECK RESULT TYPE"))))) -> Defence | L10: =IF(B10="","",IF(K10="INVALID — CHECK RESULT TYPE","",IF(K10="Transfer",D10,J10))) -> Australia | M10: =IF(B10="","",IF(K10="Transfer",C10,IFERROR(LOOKUP(2,1/($B$2:B9=B10),$M$2:M9),VLOOKUP(B10,Baseline!$A$2:$H$10,5,FALSE)))) -> 46187 | N10: =IF(B10="","",IF(K10="Transfer",0,IFERROR(LOOKUP(2,1/($B$2:B9=B10),$N$2:N9),VLOOKUP(B10,Baseline!$A$2:$H$10,6,FALSE))+IF(K10="Defence",1,0))) -> 2 | O10: =IF(B10="","",IFERROR(LOOKUP(2,1/($B$2:B9=B10),$O$2:O9),VLOOKUP(B10,Baseline!$A$2:$H$10,7,FALSE))+IF(K10="Transfer",1,0)) -> 358 | P10: =IF(B10="","",IFERROR(LOOKUP(2,1/($B$2:B9=B10),$P$2:P9),VLOOKUP(B10,Baseline!$A$2:$H$10,8,FALSE))+IF(K10="Defence",1,0)) -> 598
A11: =IF(OR(B11="",C11=""),"",VLOOKUP(B11,Lists!$A$2:$B$10,2,FALSE)&"-"&TEXT(C11,"yyyymmdd")&"-"&TEXT(COUNTIFS($B$2:B11,B11,$C$2:C11,C11),"00")) -> JEJ-20260920-01 | B11: John Edrich Jug | C11: 46285 | D11: Zimbabwe | E11: Harare Sports Club · Harare | F11: Completed | G11: Holder win | H11: def Zimbabwe by 1 wicket | J11: =IF(B11="","",IFERROR(LOOKUP(2,1/($B$2:B10=B11),$L$2:L10),VLOOKUP(B11,Baseline!$A$2:$H$10,4,FALSE))) -> Australia | K11: =IF(B11="","",IF(F11<>"Completed",F11,IF(G11="Challenger win","Transfer",IF(OR(G11="Holder win",G11="Draw / tie"),"Defence",IF(G11="No result","No result","INVALID — CHECK RESULT TYPE"))))) -> Defence | L11: =IF(B11="","",IF(K11="INVALID — CHECK RESULT TYPE","",IF(K11="Transfer",D11,J11))) -> Australia | M11: =IF(B11="","",IF(K11="Transfer",C11,IFERROR(LOOKUP(2,1/($B$2:B10=B11),$M$2:M10),VLOOKUP(B11,Baseline!$A$2:$H$10,5,FALSE)))) -> 46187 | N11: =IF(B11="","",IF(K11="Transfer",0,IFERROR(LOOKUP(2,1/($B$2:B10=B11),$N$2:N10),VLOOKUP(B11,Baseline!$A$2:$H$10,6,FALSE))+IF(K11="Defence",1,0))) -> 3 | O11: =IF(B11="","",IFERROR(LOOKUP(2,1/($B$2:B10=B11),$O$2:O10),VLOOKUP(B11,Baseline!$A$2:$H$10,7,FALSE))+IF(K11="Transfer",1,0)) -> 358 | P11: =IF(B11="","",IFERROR(LOOKUP(2,1/($B$2:B10=B11),$P$2:P10),VLOOKUP(B11,Baseline!$A$2:$H$10,8,FALSE))+IF(K11="Defence",1,0)) -> 599
A12: =IF(OR(B12="",C12=""),"",VLOOKUP(B12,Lists!$A$2:$B$10,2,FALSE)&"-"&TEXT(C12,"yyyymmdd")&"-"&TEXT(COUNTIFS($B$2:B12,B12,$C$2:C12,C12),"00")) -> JEJ-20260924-01 | B12: John Edrich Jug | C12: 46289 | D12: South Africa | E12: Durban | F12: Completed | G12: Challenger win | H12: def Australia by 67 runs | J12: =IF(B12="","",IFERROR(LOOKUP(2,1/($B$2:B11=B12),$L$2:L11),VLOOKUP(B12,Baseline!$A$2:$H$10,4,FALSE))) -> Australia | K12: =IF(B12="","",IF(F12<>"Completed",F12,IF(G12="Challenger win","Transfer",IF(OR(G12="Holder win",G12="Draw / tie"),"Defence",IF(G12="No result","No result","INVALID — CHECK RESULT TYPE"))))) -> Transfer | L12: =IF(B12="","",IF(K12="INVALID — CHECK RESULT TYPE","",IF(K12="Transfer",D12,J12))) -> South Africa | M12: =IF(B12="","",IF(K12="Transfer",C12,IFERROR(LOOKUP(2,1/($B$2:B11=B12),$M$2:M11),VLOOKUP(B12,Baseline!$A$2:$H$10,5,FALSE)))) -> 46289 | N12: =IF(B12="","",IF(K12="Transfer",0,IFERROR(LOOKUP(2,1/($B$2:B11=B12),$N$2:N11),VLOOKUP(B12,Baseline!$A$2:$H$10,6,FALSE))+IF(K12="Defence",1,0))) -> 0 | O12: =IF(B12="","",IFERROR(LOOKUP(2,1/($B$2:B11=B12),$O$2:O11),VLOOKUP(B12,Baseline!$A$2:$H$10,7,FALSE))+IF(K12="Transfer",1,0)) -> 359 | P12: =IF(B12="","",IFERROR(LOOKUP(2,1/($B$2:B11=B12),$P$2:P11),VLOOKUP(B12,Baseline!$A$2:$H$10,8,FALSE))+IF(K12="Defence",1,0)) -> 599
A13: =IF(OR(B13="",C13=""),"",VLOOKUP(B13,Lists!$A$2:$B$10,2,FALSE)&"-"&TEXT(C13,"yyyymmdd")&"-"&TEXT(COUNTIFS($B$2:B13,B13,$C$2:C13,C13),"00")) -> JEJ-20260927-01 | B13: John Edrich Jug | C13: 46292 | D13: Australia | E13: Johannesburg | F13: Completed | G13: Holder win | H13: def Australia by 32 runs | J13: =IF(B13="","",IFERROR(LOOKUP(2,1/($B$2:B12=B13),$L$2:L12),VLOOKUP(B13,Baseline!$A$2:$H$10,4,FALSE))) -> South Africa | K13: =IF(B13="","",IF(F13<>"Completed",F13,IF(G13="Challenger win","Transfer",IF(OR(G13="Holder win",G13="Draw / tie"),"Defence",IF(G13="No result","No result","INVALID — CHECK RESULT TYPE"))))) -> Defence | L13: =IF(B13="","",IF(K13="INVALID — CHECK RESULT TYPE","",IF(K13="Transfer",D13,J13))) -> South Africa | M13: =IF(B13="","",IF(K13="Transfer",C13,IFERROR(LOOKUP(2,1/($B$2:B12=B13),$M$2:M12),VLOOKUP(B13,Baseline!$A$2:$H$10,5,FALSE)))) -> 46289 | N13: =IF(B13="","",IF(K13="Transfer",0,IFERROR(LOOKUP(2,1/($B$2:B12=B13),$N$2:N12),VLOOKUP(B13,Baseline!$A$2:$H$10,6,FALSE))+IF(K13="Defence",1,0))) -> 1 | O13: =IF(B13="","",IFERROR(LOOKUP(2,1/($B$2:B12=B13),$O$2:O12),VLOOKUP(B13,Baseline!$A$2:$H$10,7,FALSE))+IF(K13="Transfer",1,0)) -> 359 | P13: =IF(B13="","",IFERROR(LOOKUP(2,1/($B$2:B12=B13),$P$2:P12),VLOOKUP(B13,Baseline!$A$2:$H$10,8,FALSE))+IF(K13="Defence",1,0)) -> 600
A14: =IF(OR(B14="",C14=""),"",VLOOKUP(B14,Lists!$A$2:$B$10,2,FALSE)&"-"&TEXT(C14,"yyyymmdd")&"-"&TEXT(COUNTIFS($B$2:B14,B14,$C$2:C14,C14),"00")) -> JEJ-20260930-01 | B14: John Edrich Jug | C14: 46295 | D14: Australia | E14: Potchefstroom | F14: Completed | G14: Challenger win | H14: def South Africa by 45 runs (DLS) | J14: =IF(B14="","",IFERROR(LOOKUP(2,1/($B$2:B13=B14),$L$2:L13),VLOOKUP(B14,Baseline!$A$2:$H$10,4,FALSE))) -> South Africa | K14: =IF(B14="","",IF(F14<>"Completed",F14,IF(G14="Challenger win","Transfer",IF(OR(G14="Holder win",G14="Draw / tie"),"Defence",IF(G14="No result","No result","INVALID — CHECK RESULT TYPE"))))) -> Transfer | L14: =IF(B14="","",IF(K14="INVALID — CHECK RESULT TYPE","",IF(K14="Transfer",D14,J14))) -> Australia | M14: =IF(B14="","",IF(K14="Transfer",C14,IFERROR(LOOKUP(2,1/($B$2:B13=B14),$M$2:M13),VLOOKUP(B14,Baseline!$A$2:$H$10,5,FALSE)))) -> 46295 | N14: =IF(B14="","",IF(K14="Transfer",0,IFERROR(LOOKUP(2,1/($B$2:B13=B14),$N$2:N13),VLOOKUP(B14,Baseline!$A$2:$H$10,6,FALSE))+IF(K14="Defence",1,0))) -> 0 | O14: =IF(B14="","",IFERROR(LOOKUP(2,1/($B$2:B13=B14),$O$2:O13),VLOOKUP(B14,Baseline!$A$2:$H$10,7,FALSE))+IF(K14="Transfer",1,0)) -> 360 | P14: =IF(B14="","",IFERROR(LOOKUP(2,1/($B$2:B13=B14),$P$2:P13),VLOOKUP(B14,Baseline!$A$2:$H$10,8,FALSE))+IF(K14="Defence",1,0)) -> 600
A15: =IF(OR(B15="",C15=""),"",VLOOKUP(B15,Lists!$A$2:$B$10,2,FALSE)&"-"&TEXT(C15,"yyyymmdd")&"-"&TEXT(COUNTIFS($B$2:B15,B15,$C$2:C15,C15),"00")) -> JEJ-20261113-01 | B15: John Edrich Jug | C15: 46339 | D15: England | E15: Perth | F15: Scheduled | J15: =IF(B15="","",IFERROR(LOOKUP(2,1/($B$2:B14=B15),$L$2:L14),VLOOKUP(B15,Baseline!$A$2:$H$10,4,FALSE))) -> Australia | K15: =IF(B15="","",IF(F15<>"Completed",F15,IF(G15="Challenger win","Transfer",IF(OR(G15="Holder win",G15="Draw / tie"),"Defence",IF(G15="No result","No result","INVALID — CHECK RESULT TYPE"))))) -> Scheduled | L15: =IF(B15="","",IF(K15="INVALID — CHECK RESULT TYPE","",IF(K15="Transfer",D15,J15))) -> Australia | M15: =IF(B15="","",IF(K15="Transfer",C15,IFERROR(LOOKUP(2,1/($B$2:B14=B15),$M$2:M14),VLOOKUP(B15,Baseline!$A$2:$H$10,5,FALSE)))) -> 46295 | N15: =IF(B15="","",IF(K15="Transfer",0,IFERROR(LOOKUP(2,1/($B$2:B14=B15),$N$2:N14),VLOOKUP(B15,Baseline!$A$2:$H$10,6,FALSE))+IF(K15="Defence",1,0))) -> 0 | O15: =IF(B15="","",IFERROR(LOOKUP(2,1/($B$2:B14=B15),$O$2:O14),VLOOKUP(B15,Baseline!$A$2:$H$10,7,FALSE))+IF(K15="Transfer",1,0)) -> 360 | P15: =IF(B15="","",IFERROR(LOOKUP(2,1/($B$2:B14=B15),$P$2:P14),VLOOKUP(B15,Baseline!$A$2:$H$10,8,FALSE))+IF(K15="Defence",1,0)) -> 600
A16: =IF(OR(B16="",C16=""),"",VLOOKUP(B16,Lists!$A$2:$B$10,2,FALSE)&"-"&TEXT(C16,"yyyymmdd")&"-"&TEXT(COUNTIFS($B$2:B16,B16,$C$2:C16,C16),"00")) -> TMT-20261011-01 | B16: Tina Macpherson Trophy | C16: 46306 | D16: Bangladesh | E16: Brisbane | F16: Completed | G16: Holder win | H16: def Bangladesh by 9 wickets | J16: =IF(B16="","",IFERROR(LOOKUP(2,1/($B$2:B15=B16),$L$2:L15),VLOOKUP(B16,Baseline!$A$2:$H$10,4,FALSE))) -> Australia | K16: =IF(B16="","",IF(F16<>"Completed",F16,IF(G16="Challenger win","Transfer",IF(OR(G16="Holder win",G16="Draw / tie"),"Defence",IF(G16="No result","No result","INVALID — CHECK RESULT TYPE"))))) -> Defence | L16: =IF(B16="","",IF(K16="INVALID — CHECK RESULT TYPE","",IF(K16="Transfer",D16,J16))) -> Australia | M16: =IF(B16="","",IF(K16="Transfer",C16,IFERROR(LOOKUP(2,1/($B$2:B15=B16),$M$2:M15),VLOOKUP(B16,Baseline!$A$2:$H$10,5,FALSE)))) -> 46077 | N16: =IF(B16="","",IF(K16="Transfer",0,IFERROR(LOOKUP(2,1/($B$2:B15=B16),$N$2:N15),VLOOKUP(B16,Baseline!$A$2:$H$10,6,FALSE))+IF(K16="Defence",1,0))) -> 7 | O16: =IF(B16="","",IFERROR(LOOKUP(2,1/($B$2:B15=B16),$O$2:O15),VLOOKUP(B16,Baseline!$A$2:$H$10,7,FALSE))+IF(K16="Transfer",1,0)) -> 120 | P16: =IF(B16="","",IFERROR(LOOKUP(2,1/($B$2:B15=B16),$P$2:P15),VLOOKUP(B16,Baseline!$A$2:$H$10,8,FALSE))+IF(K16="Defence",1,0)) -> 253
A17: =IF(OR(B17="",C17=""),"",VLOOKUP(B17,Lists!$A$2:$B$10,2,FALSE)&"-"&TEXT(C17,"yyyymmdd")&"-"&TEXT(COUNTIFS($B$2:B17,B17,$C$2:C17,C17),"00")) -> TMT-20261014-01 | B17: Tina Macpherson Trophy | C17: 46309 | D17: Bangladesh | E17: Brisbane | F17: Completed | G17: Holder win | H17: def Bangladesh by 8 wickets | J17: =IF(B17="","",IFERROR(LOOKUP(2,1/($B$2:B16=B17),$L$2:L16),VLOOKUP(B17,Baseline!$A$2:$H$10,4,FALSE))) -> Australia | K17: =IF(B17="","",IF(F17<>"Completed",F17,IF(G17="Challenger win","Transfer",IF(OR(G17="Holder win",G17="Draw / tie"),"Defence",IF(G17="No result","No result","INVALID — CHECK RESULT TYPE"))))) -> Defence | L17: =IF(B17="","",IF(K17="INVALID — CHECK RESULT TYPE","",IF(K17="Transfer",D17,J17))) -> Australia | M17: =IF(B17="","",IF(K17="Transfer",C17,IFERROR(LOOKUP(2,1/($B$2:B16=B17),$M$2:M16),VLOOKUP(B17,Baseline!$A$2:$H$10,5,FALSE)))) -> 46077 | N17: =IF(B17="","",IF(K17="Transfer",0,IFERROR(LOOKUP(2,1/($B$2:B16=B17),$N$2:N16),VLOOKUP(B17,Baseline!$A$2:$H$10,6,FALSE))+IF(K17="Defence",1,0))) -> 8 | O17: =IF(B17="","",IFERROR(LOOKUP(2,1/($B$2:B16=B17),$O$2:O16),VLOOKUP(B17,Baseline!$A$2:$H$10,7,FALSE))+IF(K17="Transfer",1,0)) -> 120 | P17: =IF(B17="","",IFERROR(LOOKUP(2,1/($B$2:B16=B17),$P$2:P16),VLOOKUP(B17,Baseline!$A$2:$H$10,8,FALSE))+IF(K17="Defence",1,0)) -> 254
A18: =IF(OR(B18="",C18=""),"",VLOOKUP(B18,Lists!$A$2:$B$10,2,FALSE)&"-"&TEXT(C18,"yyyymmdd")&"-"&TEXT(COUNTIFS($B$2:B18,B18,$C$2:C18,C18),"00")) -> CBB-20261018-01 | B18: Charles Bannerman Belt | C18: 46313 | D18: South Africa | E18: Gqebhera | F18: Scheduled | J18: =IF(B18="","",IFERROR(LOOKUP(2,1/($B$2:B17=B18),$L$2:L17),VLOOKUP(B18,Baseline!$A$2:$H$10,4,FALSE))) -> Australia | K18: =IF(B18="","",IF(F18<>"Completed",F18,IF(G18="Challenger win","Transfer",IF(OR(G18="Holder win",G18="Draw / tie"),"Defence",IF(G18="No result","No result","INVALID — CHECK RESULT TYPE"))))) -> Scheduled | L18: =IF(B18="","",IF(K18="INVALID — CHECK RESULT TYPE","",IF(K18="Transfer",D18,J18))) -> Australia | M18: =IF(B18="","",IF(K18="Transfer",C18,IFERROR(LOOKUP(2,1/($B$2:B17=B18),$M$2:M17),VLOOKUP(B18,Baseline!$A$2:$H$10,5,FALSE)))) -> 46308 | N18: =IF(B18="","",IF(K18="Transfer",0,IFERROR(LOOKUP(2,1/($B$2:B17=B18),$N$2:N17),VLOOKUP(B18,Baseline!$A$2:$H$10,6,FALSE))+IF(K18="Defence",1,0))) -> 0 | O18: =IF(B18="","",IFERROR(LOOKUP(2,1/($B$2:B17=B18),$O$2:O17),VLOOKUP(B18,Baseline!$A$2:$H$10,7,FALSE))+IF(K18="Transfer",1,0)) -> 215 | P18: =IF(B18="","",IFERROR(LOOKUP(2,1/($B$2:B17=B18),$P$2:P17),VLOOKUP(B18,Baseline!$A$2:$H$10,8,FALSE))+IF(K18="Defence",1,0)) -> 404
A19: =IF(OR(B19="",C19=""),"",VLOOKUP(B19,Lists!$A$2:$B$10,2,FALSE)&"-"&TEXT(C19,"yyyymmdd")&"-"&TEXT(COUNTIFS($B$2:B19,B19,$C$2:C19,C19),"00")) -> TMT-20261215-01 | B19: Tina Macpherson Trophy | C19: 46371 | D19: Sri Lanka | E19: Dambulla | F19: Scheduled | J19: =IF(B19="","",IFERROR(LOOKUP(2,1/($B$2:B18=B19),$L$2:L18),VLOOKUP(B19,Baseline!$A$2:$H$10,4,FALSE))) -> Australia | K19: =IF(B19="","",IF(F19<>"Completed",F19,IF(G19="Challenger win","Transfer",IF(OR(G19="Holder win",G19="Draw / tie"),"Defence",IF(G19="No result","No result","INVALID — CHECK RESULT TYPE"))))) -> Scheduled | L19: =IF(B19="","",IF(K19="INVALID — CHECK RESULT TYPE","",IF(K19="Transfer",D19,J19))) -> Australia | M19: =IF(B19="","",IF(K19="Transfer",C19,IFERROR(LOOKUP(2,1/($B$2:B18=B19),$M$2:M18),VLOOKUP(B19,Baseline!$A$2:$H$10,5,FALSE)))) -> 46077 | N19: =IF(B19="","",IF(K19="Transfer",0,IFERROR(LOOKUP(2,1/($B$2:B18=B19),$N$2:N18),VLOOKUP(B19,Baseline!$A$2:$H$10,6,FALSE))+IF(K19="Defence",1,0))) -> 8 | O19: =IF(B19="","",IFERROR(LOOKUP(2,1/($B$2:B18=B19),$O$2:O18),VLOOKUP(B19,Baseline!$A$2:$H$10,7,FALSE))+IF(K19="Transfer",1,0)) -> 120 | P19: =IF(B19="","",IFERROR(LOOKUP(2,1/($B$2:B18=B19),$P$2:P18),VLOOKUP(B19,Baseline!$A$2:$H$10,8,FALSE))+IF(K19="Defence",1,0)) -> 254
A20: =IF(OR(B20="",C20=""),"",VLOOKUP(B20,Lists!$A$2:$B$10,2,FALSE)&"-"&TEXT(C20,"yyyymmdd")&"-"&TEXT(COUNTIFS($B$2:B20,B20,$C$2:C20,C20),"00")) | J20: =IF(B20="","",IFERROR(LOOKUP(2,1/($B$2:B19=B20),$L$2:L19),VLOOKUP(B20,Baseline!$A$2:$H$10,4,FALSE))) | K20: =IF(B20="","",IF(F20<>"Completed",F20,IF(G20="Challenger win","Transfer",IF(OR(G20="Holder win",G20="Draw / tie"),"Defence",IF(G20="No result","No result","INVALID — CHECK RESULT TYPE"))))) | L20: =IF(B20="","",IF(K20="INVALID — CHECK RESULT TYPE","",IF(K20="Transfer",D20,J20))) | M20: =IF(B20="","",IF(K20="Transfer",C20,IFERROR(LOOKUP(2,1/($B$2:B19=B20),$M$2:M19),VLOOKUP(B20,Baseline!$A$2:$H$10,5,FALSE)))) | N20: =IF(B20="","",IF(K20="Transfer",0,IFERROR(LOOKUP(2,1/($B$2:B19=B20),$N$2:N19),VLOOKUP(B20,Baseline!$A$2:$H$10,6,FALSE))+IF(K20="Defence",1,0))) | O20: =IF(B20="","",IFERROR(LOOKUP(2,1/($B$2:B19=B20),$O$2:O19),VLOOKUP(B20,Baseline!$A$2:$H$10,7,FALSE))+IF(K20="Transfer",1,0)) | P20: =IF(B20="","",IFERROR(LOOKUP(2,1/($B$2:B19=B20),$P$2:P19),VLOOKUP(B20,Baseline!$A$2:$H$10,8,FALSE))+IF(K20="Defence",1,0))
A21: =IF(OR(B21="",C21=""),"",VLOOKUP(B21,Lists!$A$2:$B$10,2,FALSE)&"-"&TEXT(C21,"yyyymmdd")&"-"&TEXT(COUNTIFS($B$2:B21,B21,$C$2:C21,C21),"00")) | J21: =IF(B21="","",IFERROR(LOOKUP(2,1/($B$2:B20=B21),$L$2:L20),VLOOKUP(B21,Baseline!$A$2:$H$10,4,FALSE))) | K21: =IF(B21="","",IF(F21<>"Completed",F21,IF(G21="Challenger win","Transfer",IF(OR(G21="Holder win",G21="Draw / tie"),"Defence",IF(G21="No result","No result","INVALID — CHECK RESULT TYPE"))))) | L21: =IF(B21="","",IF(K21="INVALID — CHECK RESULT TYPE","",IF(K21="Transfer",D21,J21))) | M21: =IF(B21="","",IF(K21="Transfer",C21,IFERROR(LOOKUP(2,1/($B$2:B20=B21),$M$2:M20),VLOOKUP(B21,Baseline!$A$2:$H$10,5,FALSE)))) | N21: =IF(B21="","",IF(K21="Transfer",0,IFERROR(LOOKUP(2,1/($B$2:B20=B21),$N$2:N20),VLOOKUP(B21,Baseline!$A$2:$H$10,6,FALSE))+IF(K21="Defence",1,0))) | O21: =IF(B21="","",IFERROR(LOOKUP(2,1/($B$2:B20=B21),$O$2:O20),VLOOKUP(B21,Baseline!$A$2:$H$10,7,FALSE))+IF(K21="Transfer",1,0)) | P21: =IF(B21="","",IFERROR(LOOKUP(2,1/($B$2:B20=B21),$P$2:P20),VLOOKUP(B21,Baseline!$A$2:$H$10,8,FALSE))+IF(K21="Defence",1,0))
A22: =IF(OR(B22="",C22=""),"",VLOOKUP(B22,Lists!$A$2:$B$10,2,FALSE)&"-"&TEXT(C22,"yyyymmdd")&"-"&TEXT(COUNTIFS($B$2:B22,B22,$C$2:C22,C22),"00")) | J22: =IF(B22="","",IFERROR(LOOKUP(2,1/($B$2:B21=B22),$L$2:L21),VLOOKUP(B22,Baseline!$A$2:$H$10,4,FALSE))) | K22: =IF(B22="","",IF(F22<>"Completed",F22,IF(G22="Challenger win","Transfer",IF(OR(G22="Holder win",G22="Draw / tie"),"Defence",IF(G22="No result","No result","INVALID — CHECK RESULT TYPE"))))) | L22: =IF(B22="","",IF(K22="INVALID — CHECK RESULT TYPE","",IF(K22="Transfer",D22,J22))) | M22: =IF(B22="","",IF(K22="Transfer",C22,IFERROR(LOOKUP(2,1/($B$2:B21=B22),$M$2:M21),VLOOKUP(B22,Baseline!$A$2:$H$10,5,FALSE)))) | N22: =IF(B22="","",IF(K22="Transfer",0,IFERROR(LOOKUP(2,1/($B$2:B21=B22),$N$2:N21),VLOOKUP(B22,Baseline!$A$2:$H$10,6,FALSE))+IF(K22="Defence",1,0))) | O22: =IF(B22="","",IFERROR(LOOKUP(2,1/($B$2:B21=B22),$O$2:O21),VLOOKUP(B22,Baseline!$A$2:$H$10,7,FALSE))+IF(K22="Transfer",1,0)) | P22: =IF(B22="","",IFERROR(LOOKUP(2,1/($B$2:B21=B22),$P$2:P21),VLOOKUP(B22,Baseline!$A$2:$H$10,8,FALSE))+IF(K22="Defence",1,0))
A23: =IF(OR(B23="",C23=""),"",VLOOKUP(B23,Lists!$A$2:$B$10,2,FALSE)&"-"&TEXT(C23,"yyyymmdd")&"-"&TEXT(COUNTIFS($B$2:B23,B23,$C$2:C23,C23),"00")) | J23: =IF(B23="","",IFERROR(LOOKUP(2,1/($B$2:B22=B23),$L$2:L22),VLOOKUP(B23,Baseline!$A$2:$H$10,4,FALSE))) | K23: =IF(B23="","",IF(F23<>"Completed",F23,IF(G23="Challenger win","Transfer",IF(OR(G23="Holder win",G23="Draw / tie"),"Defence",IF(G23="No result","No result","INVALID — CHECK RESULT TYPE"))))) | L23: =IF(B23="","",IF(K23="INVALID — CHECK RESULT TYPE","",IF(K23="Transfer",D23,J23))) | M23: =IF(B23="","",IF(K23="Transfer",C23,IFERROR(LOOKUP(2,1/($B$2:B22=B23),$M$2:M22),VLOOKUP(B23,Baseline!$A$2:$H$10,5,FALSE)))) | N23: =IF(B23="","",IF(K23="Transfer",0,IFERROR(LOOKUP(2,1/($B$2:B22=B23),$N$2:N22),VLOOKUP(B23,Baseline!$A$2:$H$10,6,FALSE))+IF(K23="Defence",1,0))) | O23: =IF(B23="","",IFERROR(LOOKUP(2,1/($B$2:B22=B23),$O$2:O22),VLOOKUP(B23,Baseline!$A$2:$H$10,7,FALSE))+IF(K23="Transfer",1,0)) | P23: =IF(B23="","",IFERROR(LOOKUP(2,1/($B$2:B22=B23),$P$2:P22),VLOOKUP(B23,Baseline!$A$2:$H$10,8,FALSE))+IF(K23="Defence",1,0))
A24: =IF(OR(B24="",C24=""),"",VLOOKUP(B24,Lists!$A$2:$B$10,2,FALSE)&"-"&TEXT(C24,"yyyymmdd")&"-"&TEXT(COUNTIFS($B$2:B24,B24,$C$2:C24,C24),"00")) | J24: =IF(B24="","",IFERROR(LOOKUP(2,1/($B$2:B23=B24),$L$2:L23),VLOOKUP(B24,Baseline!$A$2:$H$10,4,FALSE))) | K24: =IF(B24="","",IF(F24<>"Completed",F24,IF(G24="Challenger win","Transfer",IF(OR(G24="Holder win",G24="Draw / tie"),"Defence",IF(G24="No result","No result","INVALID — CHECK RESULT TYPE"))))) | L24: =IF(B24="","",IF(K24="INVALID — CHECK RESULT TYPE","",IF(K24="Transfer",D24,J24))) | M24: =IF(B24="","",IF(K24="Transfer",C24,IFERROR(LOOKUP(2,1/($B$2:B23=B24),$M$2:M23),VLOOKUP(B24,Baseline!$A$2:$H$10,5,FALSE)))) | N24: =IF(B24="","",IF(K24="Transfer",0,IFERROR(LOOKUP(2,1/($B$2:B23=B24),$N$2:N23),VLOOKUP(B24,Baseline!$A$2:$H$10,6,FALSE))+IF(K24="Defence",1,0))) | O24: =IF(B24="","",IFERROR(LOOKUP(2,1/($B$2:B23=B24),$O$2:O23),VLOOKUP(B24,Baseline!$A$2:$H$10,7,FALSE))+IF(K24="Transfer",1,0)) | P24: =IF(B24="","",IFERROR(LOOKUP(2,1/($B$2:B23=B24),$P$2:P23),VLOOKUP(B24,Baseline!$A$2:$H$10,8,FALSE))+IF(K24="Defence",1,0))
A25: =IF(OR(B25="",C25=""),"",VLOOKUP(B25,Lists!$A$2:$B$10,2,FALSE)&"-"&TEXT(C25,"yyyymmdd")&"-"&TEXT(COUNTIFS($B$2:B25,B25,$C$2:C25,C25),"00")) | J25: =IF(B25="","",IFERROR(LOOKUP(2,1/($B$2:B24=B25),$L$2:L24),VLOOKUP(B25,Baseline!$A$2:$H$10,4,FALSE))) | K25: =IF(B25="","",IF(F25<>"Completed",F25,IF(G25="Challenger win","Transfer",IF(OR(G25="Holder win",G25="Draw / tie"),"Defence",IF(G25="No result","No result","INVALID — CHECK RESULT TYPE"))))) | L25: =IF(B25="","",IF(K25="INVALID — CHECK RESULT TYPE","",IF(K25="Transfer",D25,J25))) | M25: =IF(B25="","",IF(K25="Transfer",C25,IFERROR(LOOKUP(2,1/($B$2:B24=B25),$M$2:M24),VLOOKUP(B25,Baseline!$A$2:$H$10,5,FALSE)))) | N25: =IF(B25="","",IF(K25="Transfer",0,IFERROR(LOOKUP(2,1/($B$2:B24=B25),$N$2:N24),VLOOKUP(B25,Baseline!$A$2:$H$10,6,FALSE))+IF(K25="Defence",1,0))) | O25: =IF(B25="","",IFERROR(LOOKUP(2,1/($B$2:B24=B25),$O$2:O24),VLOOKUP(B25,Baseline!$A$2:$H$10,7,FALSE))+IF(K25="Transfer",1,0)) | P25: =IF(B25="","",IFERROR(LOOKUP(2,1/($B$2:B24=B25),$P$2:P24),VLOOKUP(B25,Baseline!$A$2:$H$10,8,FALSE))+IF(K25="Defence",1,0))
A26: =IF(OR(B26="",C26=""),"",VLOOKUP(B26,Lists!$A$2:$B$10,2,FALSE)&"-"&TEXT(C26,"yyyymmdd")&"-"&TEXT(COUNTIFS($B$2:B26,B26,$C$2:C26,C26),"00")) | J26: =IF(B26="","",IFERROR(LOOKUP(2,1/($B$2:B25=B26),$L$2:L25),VLOOKUP(B26,Baseline!$A$2:$H$10,4,FALSE))) | K26: =IF(B26="","",IF(F26<>"Completed",F26,IF(G26="Challenger win","Transfer",IF(OR(G26="Holder win",G26="Draw / tie"),"Defence",IF(G26="No result","No result","INVALID — CHECK RESULT TYPE"))))) | L26: =IF(B26="","",IF(K26="INVALID — CHECK RESULT TYPE","",IF(K26="Transfer",D26,J26))) | M26: =IF(B26="","",IF(K26="Transfer",C26,IFERROR(LOOKUP(2,1/($B$2:B25=B26),$M$2:M25),VLOOKUP(B26,Baseline!$A$2:$H$10,5,FALSE)))) | N26: =IF(B26="","",IF(K26="Transfer",0,IFERROR(LOOKUP(2,1/($B$2:B25=B26),$N$2:N25),VLOOKUP(B26,Baseline!$A$2:$H$10,6,FALSE))+IF(K26="Defence",1,0))) | O26: =IF(B26="","",IFERROR(LOOKUP(2,1/($B$2:B25=B26),$O$2:O25),VLOOKUP(B26,Baseline!$A$2:$H$10,7,FALSE))+IF(K26="Transfer",1,0)) | P26: =IF(B26="","",IFERROR(LOOKUP(2,1/($B$2:B25=B26),$P$2:P25),VLOOKUP(B26,Baseline!$A$2:$H$10,8,FALSE))+IF(K26="Defence",1,0))
A27: =IF(OR(B27="",C27=""),"",VLOOKUP(B27,Lists!$A$2:$B$10,2,FALSE)&"-"&TEXT(C27,"yyyymmdd")&"-"&TEXT(COUNTIFS($B$2:B27,B27,$C$2:C27,C27),"00")) | J27: =IF(B27="","",IFERROR(LOOKUP(2,1/($B$2:B26=B27),$L$2:L26),VLOOKUP(B27,Baseline!$A$2:$H$10,4,FALSE))) | K27: =IF(B27="","",IF(F27<>"Completed",F27,IF(G27="Challenger win","Transfer",IF(OR(G27="Holder win",G27="Draw / tie"),"Defence",IF(G27="No result","No result","INVALID — CHECK RESULT TYPE"))))) | L27: =IF(B27="","",IF(K27="INVALID — CHECK RESULT TYPE","",IF(K27="Transfer",D27,J27))) | M27: =IF(B27="","",IF(K27="Transfer",C27,IFERROR(LOOKUP(2,1/($B$2:B26=B27),$M$2:M26),VLOOKUP(B27,Baseline!$A$2:$H$10,5,FALSE)))) | N27: =IF(B27="","",IF(K27="Transfer",0,IFERROR(LOOKUP(2,1/($B$2:B26=B27),$N$2:N26),VLOOKUP(B27,Baseline!$A$2:$H$10,6,FALSE))+IF(K27="Defence",1,0))) | O27: =IF(B27="","",IFERROR(LOOKUP(2,1/($B$2:B26=B27),$O$2:O26),VLOOKUP(B27,Baseline!$A$2:$H$10,7,FALSE))+IF(K27="Transfer",1,0)) | P27: =IF(B27="","",IFERROR(LOOKUP(2,1/($B$2:B26=B27),$P$2:P26),VLOOKUP(B27,Baseline!$A$2:$H$10,8,FALSE))+IF(K27="Defence",1,0))
A28: =IF(OR(B28="",C28=""),"",VLOOKUP(B28,Lists!$A$2:$B$10,2,FALSE)&"-"&TEXT(C28,"yyyymmdd")&"-"&TEXT(COUNTIFS($B$2:B28,B28,$C$2:C28,C28),"00")) | J28: =IF(B28="","",IFERROR(LOOKUP(2,1/($B$2:B27=B28),$L$2:L27),VLOOKUP(B28,Baseline!$A$2:$H$10,4,FALSE))) | K28: =IF(B28="","",IF(F28<>"Completed",F28,IF(G28="Challenger win","Transfer",IF(OR(G28="Holder win",G28="Draw / tie"),"Defence",IF(G28="No result","No result","INVALID — CHECK RESULT TYPE"))))) | L28: =IF(B28="","",IF(K28="INVALID — CHECK RESULT TYPE","",IF(K28="Transfer",D28,J28))) | M28: =IF(B28="","",IF(K28="Transfer",C28,IFERROR(LOOKUP(2,1/($B$2:B27=B28),$M$2:M27),VLOOKUP(B28,Baseline!$A$2:$H$10,5,FALSE)))) | N28: =IF(B28="","",IF(K28="Transfer",0,IFERROR(LOOKUP(2,1/($B$2:B27=B28),$N$2:N27),VLOOKUP(B28,Baseline!$A$2:$H$10,6,FALSE))+IF(K28="Defence",1,0))) | O28: =IF(B28="","",IFERROR(LOOKUP(2,1/($B$2:B27=B28),$O$2:O27),VLOOKUP(B28,Baseline!$A$2:$H$10,7,FALSE))+IF(K28="Transfer",1,0)) | P28: =IF(B28="","",IFERROR(LOOKUP(2,1/($B$2:B27=B28),$P$2:P27),VLOOKUP(B28,Baseline!$A$2:$H$10,8,FALSE))+IF(K28="Defence",1,0))
A29: =IF(OR(B29="",C29=""),"",VLOOKUP(B29,Lists!$A$2:$B$10,2,FALSE)&"-"&TEXT(C29,"yyyymmdd")&"-"&TEXT(COUNTIFS($B$2:B29,B29,$C$2:C29,C29),"00")) | J29: =IF(B29="","",IFERROR(LOOKUP(2,1/($B$2:B28=B29),$L$2:L28),VLOOKUP(B29,Baseline!$A$2:$H$10,4,FALSE))) | K29: =IF(B29="","",IF(F29<>"Completed",F29,IF(G29="Challenger win","Transfer",IF(OR(G29="Holder win",G29="Draw / tie"),"Defence",IF(G29="No result","No result","INVALID — CHECK RESULT TYPE"))))) | L29: =IF(B29="","",IF(K29="INVALID — CHECK RESULT TYPE","",IF(K29="Transfer",D29,J29))) | M29: =IF(B29="","",IF(K29="Transfer",C29,IFERROR(LOOKUP(2,1/($B$2:B28=B29),$M$2:M28),VLOOKUP(B29,Baseline!$A$2:$H$10,5,FALSE)))) | N29: =IF(B29="","",IF(K29="Transfer",0,IFERROR(LOOKUP(2,1/($B$2:B28=B29),$N$2:N28),VLOOKUP(B29,Baseline!$A$2:$H$10,6,FALSE))+IF(K29="Defence",1,0))) | O29: =IF(B29="","",IFERROR(LOOKUP(2,1/($B$2:B28=B29),$O$2:O28),VLOOKUP(B29,Baseline!$A$2:$H$10,7,FALSE))+IF(K29="Transfer",1,0)) | P29: =IF(B29="","",IFERROR(LOOKUP(2,1/($B$2:B28=B29),$P$2:P28),VLOOKUP(B29,Baseline!$A$2:$H$10,8,FALSE))+IF(K29="Defence",1,0))
A30: =IF(OR(B30="",C30=""),"",VLOOKUP(B30,Lists!$A$2:$B$10,2,FALSE)&"-"&TEXT(C30,"yyyymmdd")&"-"&TEXT(COUNTIFS($B$2:B30,B30,$C$2:C30,C30),"00")) | J30: =IF(B30="","",IFERROR(LOOKUP(2,1/($B$2:B29=B30),$L$2:L29),VLOOKUP(B30,Baseline!$A$2:$H$10,4,FALSE))) | K30: =IF(B30="","",IF(F30<>"Completed",F30,IF(G30="Challenger win","Transfer",IF(OR(G30="Holder win",G30="Draw / tie"),"Defence",IF(G30="No result","No result","INVALID — CHECK RESULT TYPE"))))) | L30: =IF(B30="","",IF(K30="INVALID — CHECK RESULT TYPE","",IF(K30="Transfer",D30,J30))) | M30: =IF(B30="","",IF(K30="Transfer",C30,IFERROR(LOOKUP(2,1/($B$2:B29=B30),$M$2:M29),VLOOKUP(B30,Baseline!$A$2:$H$10,5,FALSE)))) | N30: =IF(B30="","",IF(K30="Transfer",0,IFERROR(LOOKUP(2,1/($B$2:B29=B30),$N$2:N29),VLOOKUP(B30,Baseline!$A$2:$H$10,6,FALSE))+IF(K30="Defence",1,0))) | O30: =IF(B30="","",IFERROR(LOOKUP(2,1/($B$2:B29=B30),$O$2:O29),VLOOKUP(B30,Baseline!$A$2:$H$10,7,FALSE))+IF(K30="Transfer",1,0)) | P30: =IF(B30="","",IFERROR(LOOKUP(2,1/($B$2:B29=B30),$P$2:P29),VLOOKUP(B30,Baseline!$A$2:$H$10,8,FALSE))+IF(K30="Defence",1,0))
A31: =IF(OR(B31="",C31=""),"",VLOOKUP(B31,Lists!$A$2:$B$10,2,FALSE)&"-"&TEXT(C31,"yyyymmdd")&"-"&TEXT(COUNTIFS($B$2:B31,B31,$C$2:C31,C31),"00")) | J31: =IF(B31="","",IFERROR(LOOKUP(2,1/($B$2:B30=B31),$L$2:L30),VLOOKUP(B31,Baseline!$A$2:$H$10,4,FALSE))) | K31: =IF(B31="","",IF(F31<>"Completed",F31,IF(G31="Challenger win","Transfer",IF(OR(G31="Holder win",G31="Draw / tie"),"Defence",IF(G31="No result","No result","INVALID — CHECK RESULT TYPE"))))) | L31: =IF(B31="","",IF(K31="INVALID — CHECK RESULT TYPE","",IF(K31="Transfer",D31,J31))) | M31: =IF(B31="","",IF(K31="Transfer",C31,IFERROR(LOOKUP(2,1/($B$2:B30=B31),$M$2:M30),VLOOKUP(B31,Baseline!$A$2:$H$10,5,FALSE)))) | N31: =IF(B31="","",IF(K31="Transfer",0,IFERROR(LOOKUP(2,1/($B$2:B30=B31),$N$2:N30),VLOOKUP(B31,Baseline!$A$2:$H$10,6,FALSE))+IF(K31="Defence",1,0))) | O31: =IF(B31="","",IFERROR(LOOKUP(2,1/($B$2:B30=B31),$O$2:O30),VLOOKUP(B31,Baseline!$A$2:$H$10,7,FALSE))+IF(K31="Transfer",1,0)) | P31: =IF(B31="","",IFERROR(LOOKUP(2,1/($B$2:B30=B31),$P$2:P30),VLOOKUP(B31,Baseline!$A$2:$H$10,8,FALSE))+IF(K31="Defence",1,0))
... A33: =IF(OR(B33="",C33=""),"",VLOOKUP(B33,Lists!$A$2:$B$10,2,FALSE)&"-"&TEXT(C33,"yyyymmdd")&"-"&TEXT(COUNTIFS($B$2:B33,B33,$C$2:C33,C33),"00")) | J33: =IF(B33="","",IFERROR(LOOKUP(2,1/($B$2:B32=B33),$L$2:L32),VLOOKUP(B33,Baseline!$A$2:$H$10,4,FALSE))) | K33: =IF(B33="","",IF(F33<>"Completed",F33,IF(G33="Challenger win","Transfer",IF(OR(G33="Holder win",G33="Draw / tie"),"Defence",IF(G33="No result","No result","INVALID — CHECK RESULT TYPE"))))) | L33: =IF(B33="","",IF(K33="INVALID — CHECK RESULT TYPE","",IF(K33="Transfer",D33,J33))) | M33: =IF(B33="","",IF(K33="Transfer",C33,IFERROR(LOOKUP(2,1/($B$2:B32=B33),$M$2:M32),VLOOKUP(B33,Baseline!$A$2:$H$10,5,FALSE)))) | N33: =IF(B33="","",IF(K33="Transfer",0,IFERROR(LOOKUP(2,1/($B$2:B32=B33),$N$2:N32),VLOOKUP(B33,Baseline!$A$2:$H$10,6,FALSE))+IF(K33="Defence",1,0))) | O33: =IF(B33="","",IFERROR(LOOKUP(2,1/($B$2:B32=B33),$O$2:O32),VLOOKUP(B33,Baseline!$A$2:$H$10,7,FALSE))+IF(K33="Transfer",1,0)) | P33: =IF(B33="","",IFERROR(LOOKUP(2,1/($B$2:B32=B33),$P$2:P32),VLOOKUP(B33,Baseline!$A$2:$H$10,8,FALSE))+IF(K33="Defence",1,0))
A34: =IF(OR(B34="",C34=""),"",VLOOKUP(B34,Lists!$A$2:$B$10,2,FALSE)&"-"&TEXT(C34,"yyyymmdd")&"-"&TEXT(COUNTIFS($B$2:B34,B34,$C$2:C34,C34),"00")) | J34: =IF(B34="","",IFERROR(LOOKUP(2,1/($B$2:B33=B34),$L$2:L33),VLOOKUP(B34,Baseline!$A$2:$H$10,4,FALSE))) | K34: =IF(B34="","",IF(F34<>"Completed",F34,IF(G34="Challenger win","Transfer",IF(OR(G34="Holder win",G34="Draw / tie"),"Defence",IF(G34="No result","No result","REVIEW"))))) | L34: =IF(B34="","",IF(K34="Transfer",D34,J34)) | M34: =IF(B34="","",IF(K34="Transfer",C34,IFERROR(LOOKUP(2,1/($B$2:B33=B34),$M$2:M33),VLOOKUP(B34,Baseline!$A$2:$H$10,5,FALSE)))) | N34: =IF(B34="","",IF(K34="Transfer",0,IFERROR(LOOKUP(2,1/($B$2:B33=B34),$N$2:N33),VLOOKUP(B34,Baseline!$A$2:$H$10,6,FALSE))+IF(K34="Defence",1,0))) | O34: =IF(B34="","",IFERROR(LOOKUP(2,1/($B$2:B33=B34),$O$2:O33),VLOOKUP(B34,Baseline!$A$2:$H$10,7,FALSE))+IF(K34="Transfer",1,0)) | P34: =IF(B34="","",IFERROR(LOOKUP(2,1/($B$2:B33=B34),$P$2:P33),VLOOKUP(B34,Baseline!$A$2:$H$10,8,FALSE))+IF(K34="Defence",1,0))
A35: =IF(OR(B35="",C35=""),"",VLOOKUP(B35,Lists!$A$2:$B$10,2,FALSE)&"-"&TEXT(C35,"yyyymmdd")&"-"&TEXT(COUNTIFS($B$2:B35,B35,$C$2:C35,C35),"00")) | J35: =IF(B35="","",IFERROR(LOOKUP(2,1/($B$2:B34=B35),$L$2:L34),VLOOKUP(B35,Baseline!$A$2:$H$10,4,FALSE))) | K35: =IF(B35="","",IF(F35<>"Completed",F35,IF(G35="Challenger win","Transfer",IF(OR(G35="Holder win",G35="Draw / tie"),"Defence",IF(G35="No result","No result","REVIEW"))))) | L35: =IF(B35="","",IF(K35="Transfer",D35,J35)) | M35: =IF(B35="","",IF(K35="Transfer",C35,IFERROR(LOOKUP(2,1/($B$2:B34=B35),$M$2:M34),VLOOKUP(B35,Baseline!$A$2:$H$10,5,FALSE)))) | N35: =IF(B35="","",IF(K35="Transfer",0,IFERROR(LOOKUP(2,1/($B$2:B34=B35),$N$2:N34),VLOOKUP(B35,Baseline!$A$2:$H$10,6,FALSE))+IF(K35="Defence",1,0))) | O35: =IF(B35="","",IFERROR(LOOKUP(2,1/($B$2:B34=B35),$O$2:O34),VLOOKUP(B35,Baseline!$A$2:$H$10,7,FALSE))+IF(K35="Transfer",1,0)) | P35: =IF(B35="","",IFERROR(LOOKUP(2,1/($B$2:B34=B35),$P$2:P34),VLOOKUP(B35,Baseline!$A$2:$H$10,8,FALSE))+IF(K35="Defence",1,0))
A36: =IF(OR(B36="",C36=""),"",VLOOKUP(B36,Lists!$A$2:$B$10,2,FALSE)&"-"&TEXT(C36,"yyyymmdd")&"-"&TEXT(COUNTIFS($B$2:B36,B36,$C$2:C36,C36),"00")) | J36: =IF(B36="","",IFERROR(LOOKUP(2,1/($B$2:B35=B36),$L$2:L35),VLOOKUP(B36,Baseline!$A$2:$H$10,4,FALSE))) | K36: =IF(B36="","",IF(F36<>"Completed",F36,IF(G36="Challenger win","Transfer",IF(OR(G36="Holder win",G36="Draw / tie"),"Defence",IF(G36="No result","No result","REVIEW"))))) | L36: =IF(B36="","",IF(K36="Transfer",D36,J36)) | M36: =IF(B36="","",IF(K36="Transfer",C36,IFERROR(LOOKUP(2,1/($B$2:B35=B36),$M$2:M35),VLOOKUP(B36,Baseline!$A$2:$H$10,5,FALSE)))) | N36: =IF(B36="","",IF(K36="Transfer",0,IFERROR(LOOKUP(2,1/($B$2:B35=B36),$N$2:N35),VLOOKUP(B36,Baseline!$A$2:$H$10,6,FALSE))+IF(K36="Defence",1,0))) | O36: =IF(B36="","",IFERROR(LOOKUP(2,1/($B$2:B35=B36),$O$2:O35),VLOOKUP(B36,Baseline!$A$2:$H$10,7,FALSE))+IF(K36="Transfer",1,0)) | P36: =IF(B36="","",IFERROR(LOOKUP(2,1/($B$2:B35=B36),$P$2:P35),VLOOKUP(B36,Baseline!$A$2:$H$10,8,FALSE))+IF(K36="Defence",1,0))
A37: =IF(OR(B37="",C37=""),"",VLOOKUP(B37,Lists!$A$2:$B$10,2,FALSE)&"-"&TEXT(C37,"yyyymmdd")&"-"&TEXT(COUNTIFS($B$2:B37,B37,$C$2:C37,C37),"00")) | J37: =IF(B37="","",IFERROR(LOOKUP(2,1/($B$2:B36=B37),$L$2:L36),VLOOKUP(B37,Baseline!$A$2:$H$10,4,FALSE))) | K37: =IF(B37="","",IF(F37<>"Completed",F37,IF(G37="Challenger win","Transfer",IF(OR(G37="Holder win",G37="Draw / tie"),"Defence",IF(G37="No result","No result","REVIEW"))))) | L37: =IF(B37="","",IF(K37="Transfer",D37,J37)) | M37: =IF(B37="","",IF(K37="Transfer",C37,IFERROR(LOOKUP(2,1/($B$2:B36=B37),$M$2:M36),VLOOKUP(B37,Baseline!$A$2:$H$10,5,FALSE)))) | N37: =IF(B37="","",IF(K37="Transfer",0,IFERROR(LOOKUP(2,1/($B$2:B36=B37),$N$2:N36),VLOOKUP(B37,Baseline!$A$2:$H$10,6,FALSE))+IF(K37="Defence",1,0))) | O37: =IF(B37="","",IFERROR(LOOKUP(2,1/($B$2:B36=B37),$O$2:O36),VLOOKUP(B37,Baseline!$A$2:$H$10,7,FALSE))+IF(K37="Transfer",1,0)) | P37: =IF(B37="","",IFERROR(LOOKUP(2,1/($B$2:B36=B37),$P$2:P36),VLOOKUP(B37,Baseline!$A$2:$H$10,8,FALSE))+IF(K37="Defence",1,0))
A38: =IF(OR(B38="",C38=""),"",VLOOKUP(B38,Lists!$A$2:$B$10,2,FALSE)&"-"&TEXT(C38,"yyyymmdd")&"-"&TEXT(COUNTIFS($B$2:B38,B38,$C$2:C38,C38),"00")) | J38: =IF(B38="","",IFERROR(LOOKUP(2,1/($B$2:B37=B38),$L$2:L37),VLOOKUP(B38,Baseline!$A$2:$H$10,4,FALSE))) | K38: =IF(B38="","",IF(F38<>"Completed",F38,IF(G38="Challenger win","Transfer",IF(OR(G38="Holder win",G38="Draw / tie"),"Defence",IF(G38="No result","No result","REVIEW"))))) | L38: =IF(B38="","",IF(K38="Transfer",D38,J38)) | M38: =IF(B38="","",IF(K38="Transfer",C38,IFERROR(LOOKUP(2,1/($B$2:B37=B38),$M$2:M37),VLOOKUP(B38,Baseline!$A$2:$H$10,5,FALSE)))) | N38: =IF(B38="","",IF(K38="Transfer",0,IFERROR(LOOKUP(2,1/($B$2:B37=B38),$N$2:N37),VLOOKUP(B38,Baseline!$A$2:$H$10,6,FALSE))+IF(K38="Defence",1,0))) | O38: =IF(B38="","",IFERROR(LOOKUP(2,1/($B$2:B37=B38),$O$2:O37),VLOOKUP(B38,Baseline!$A$2:$H$10,7,FALSE))+IF(K38="Transfer",1,0)) | P38: =IF(B38="","",IFERROR(LOOKUP(2,1/($B$2:B37=B38),$P$2:P37),VLOOKUP(B38,Baseline!$A$2:$H$10,8,FALSE))+IF(K38="Defence",1,0))
A39: =IF(OR(B39="",C39=""),"",VLOOKUP(B39,Lists!$A$2:$B$10,2,FALSE)&"-"&TEXT(C39,"yyyymmdd")&"-"&TEXT(COUNTIFS($B$2:B39,B39,$C$2:C39,C39),"00")) | J39: =IF(B39="","",IFERROR(LOOKUP(2,1/($B$2:B38=B39),$L$2:L38),VLOOKUP(B39,Baseline!$A$2:$H$10,4,FALSE))) | K39: =IF(B39="","",IF(F39<>"Completed",F39,IF(G39="Challenger win","Transfer",IF(OR(G39="Holder win",G39="Draw / tie"),"Defence",IF(G39="No result","No result","REVIEW"))))) | L39: =IF(B39="","",IF(K39="Transfer",D39,J39)) | M39: =IF(B39="","",IF(K39="Transfer",C39,IFERROR(LOOKUP(2,1/($B$2:B38=B39),$M$2:M38),VLOOKUP(B39,Baseline!$A$2:$H$10,5,FALSE)))) | N39: =IF(B39="","",IF(K39="Transfer",0,IFERROR(LOOKUP(2,1/($B$2:B38=B39),$N$2:N38),VLOOKUP(B39,Baseline!$A$2:$H$10,6,FALSE))+IF(K39="Defence",1,0))) | O39: =IF(B39="","",IFERROR(LOOKUP(2,1/($B$2:B38=B39),$O$2:O38),VLOOKUP(B39,Baseline!$A$2:$H$10,7,FALSE))+IF(K39="Transfer",1,0)) | P39: =IF(B39="","",IFERROR(LOOKUP(2,1/($B$2:B38=B39),$P$2:P38),VLOOKUP(B39,Baseline!$A$2:$H$10,8,FALSE))+IF(K39="Defence",1,0))
A40: =IF(OR(B40="",C40=""),"",VLOOKUP(B40,Lists!$A$2:$B$10,2,FALSE)&"-"&TEXT(C40,"yyyymmdd")&"-"&TEXT(COUNTIFS($B$2:B40,B40,$C$2:C40,C40),"00")) | J40: =IF(B40="","",IFERROR(LOOKUP(2,1/($B$2:B39=B40),$L$2:L39),VLOOKUP(B40,Baseline!$A$2:$H$10,4,FALSE))) | K40: =IF(B40="","",IF(F40<>"Completed",F40,IF(G40="Challenger win","Transfer",IF(OR(G40="Holder win",G40="Draw / tie"),"Defence",IF(G40="No result","No result","REVIEW"))))) | L40: =IF(B40="","",IF(K40="Transfer",D40,J40)) | M40: =IF(B40="","",IF(K40="Transfer",C40,IFERROR(LOOKUP(2,1/($B$2:B39=B40),$M$2:M39),VLOOKUP(B40,Baseline!$A$2:$H$10,5,FALSE)))) | N40: =IF(B40="","",IF(K40="Transfer",0,IFERROR(LOOKUP(2,1/($B$2:B39=B40),$N$2:N39),VLOOKUP(B40,Baseline!$A$2:$H$10,6,FALSE))+IF(K40="Defence",1,0))) | O40: =IF(B40="","",IFERROR(LOOKUP(2,1/($B$2:B39=B40),$O$2:O39),VLOOKUP(B40,Baseline!$A$2:$H$10,7,FALSE))+IF(K40="Transfer",1,0)) | P40: =IF(B40="","",IFERROR(LOOKUP(2,1/($B$2:B39=B40),$P$2:P39),VLOOKUP(B40,Baseline!$A$2:$H$10,8,FALSE))+IF(K40="Defence",1,0))
A41: =IF(OR(B41="",C41=""),"",VLOOKUP(B41,Lists!$A$2:$B$10,2,FALSE)&"-"&TEXT(C41,"yyyymmdd")&"-"&TEXT(COUNTIFS($B$2:B41,B41,$C$2:C41,C41),"00")) | J41: =IF(B41="","",IFERROR(LOOKUP(2,1/($B$2:B40=B41),$L$2:L40),VLOOKUP(B41,Baseline!$A$2:$H$10,4,FALSE))) | K41: =IF(B41="","",IF(F41<>"Completed",F41,IF(G41="Challenger win","Transfer",IF(OR(G41="Holder win",G41="Draw / tie"),"Defence",IF(G41="No result","No result","REVIEW"))))) | L41: =IF(B41="","",IF(K41="Transfer",D41,J41)) | M41: =IF(B41="","",IF(K41="Transfer",C41,IFERROR(LOOKUP(2,1/($B$2:B40=B41),$M$2:M40),VLOOKUP(B41,Baseline!$A$2:$H$10,5,FALSE)))) | N41: =IF(B41="","",IF(K41="Transfer",0,IFERROR(LOOKUP(2,1/($B$2:B40=B41),$N$2:N40),VLOOKUP(B41,Baseline!$A$2:$H$10,6,FALSE))+IF(K41="Defence",1,0))) | O41: =IF(B41="","",IFERROR(LOOKUP(2,1/($B$2:B40=B41),$O$2:O40),VLOOKUP(B41,Baseline!$A$2:$H$10,7,FALSE))+IF(K41="Transfer",1,0)) | P41: =IF(B41="","",IFERROR(LOOKUP(2,1/($B$2:B40=B41),$P$2:P40),VLOOKUP(B41,Baseline!$A$2:$H$10,8,FALSE))+IF(K41="Defence",1,0))
...

Sheet Dashboard
A1: Championship | B1: Current Holder | C1: Since | D1: Current Defences | E1: Transfers | F1: Total Defences | G1: Next Date | H1: Next Opponent
A2: Charles Bannerman Belt | B2: =IFERROR(LOOKUP(2,1/(Updates!$B$2:$B$100=A2),Updates!$L$2:$L$100),VLOOKUP(A2,Baseline!$A$2:$H$10,4,FALSE)) -> Australia | C2: =IFERROR(LOOKUP(2,1/(Updates!$B$2:$B$100=A2),Updates!$M$2:$M$100),VLOOKUP(A2,Baseline!$A$2:$H$10,5,FALSE)) -> 46308 | D2: =IFERROR(LOOKUP(2,1/(Updates!$B$2:$B$100=A2),Updates!$N$2:$N$100),VLOOKUP(A2,Baseline!$A$2:$H$10,6,FALSE)) -> 0 | E2: =IFERROR(LOOKUP(2,1/(Updates!$B$2:$B$100=A2),Updates!$O$2:$O$100),VLOOKUP(A2,Baseline!$A$2:$H$10,7,FALSE)) -> 215 | F2: =IFERROR(LOOKUP(2,1/(Updates!$B$2:$B$100=A2),Updates!$P$2:$P$100),VLOOKUP(A2,Baseline!$A$2:$H$10,8,FALSE)) -> 404 | G2: =IFERROR(LOOKUP(2,1/((Updates!$B$2:$B$100=A2)*(Updates!$F$2:$F$100<>"Completed")*(Updates!$F$2:$F$100<>"Cancelled")*(Updates!$F$2:$F$100<>"Postponed")),Updates!$C$2:$C$100),"TBD") -> 46313 | H2: =IF(G2="TBD","TBD",IFERROR(LOOKUP(2,1/((Updates!$B$2:$B$100=A2)*(Updates!$C$2:$C$100=G2)),Updates!$D$2:$D$100),"TBD")) -> South Africa
A3: Myrtle Maclagan Medal | B3: =IFERROR(LOOKUP(2,1/(Updates!$B$2:$B$100=A3),Updates!$L$2:$L$100),VLOOKUP(A3,Baseline!$A$2:$H$10,4,FALSE)) -> Australia | C3: =IFERROR(LOOKUP(2,1/(Updates!$B$2:$B$100=A3),Updates!$M$2:$M$100),VLOOKUP(A3,Baseline!$A$2:$H$10,5,FALSE)) -> 46089 | D3: =IFERROR(LOOKUP(2,1/(Updates!$B$2:$B$100=A3),Updates!$N$2:$N$100),VLOOKUP(A3,Baseline!$A$2:$H$10,6,FALSE)) -> 0 | E3: =IFERROR(LOOKUP(2,1/(Updates!$B$2:$B$100=A3),Updates!$O$2:$O$100),VLOOKUP(A3,Baseline!$A$2:$H$10,7,FALSE)) -> 8 | F3: =IFERROR(LOOKUP(2,1/(Updates!$B$2:$B$100=A3),Updates!$P$2:$P$100),VLOOKUP(A3,Baseline!$A$2:$H$10,8,FALSE)) -> 74 | G3: =IFERROR(LOOKUP(2,1/((Updates!$B$2:$B$100=A3)*(Updates!$F$2:$F$100<>"Completed")*(Updates!$F$2:$F$100<>"Cancelled")*(Updates!$F$2:$F$100<>"Postponed")),Updates!$C$2:$C$100),"TBD") -> 46485 | H3: =IF(G3="TBD","TBD",IFERROR(LOOKUP(2,1/((Updates!$B$2:$B$100=A3)*(Updates!$C$2:$C$100=G3)),Updates!$D$2:$D$100),"TBD")) -> South Africa
A4: John Edrich Jug | B4: =IFERROR(LOOKUP(2,1/(Updates!$B$2:$B$100=A4),Updates!$L$2:$L$100),VLOOKUP(A4,Baseline!$A$2:$H$10,4,FALSE)) -> Australia | C4: =IFERROR(LOOKUP(2,1/(Updates!$B$2:$B$100=A4),Updates!$M$2:$M$100),VLOOKUP(A4,Baseline!$A$2:$H$10,5,FALSE)) -> 46295 | D4: =IFERROR(LOOKUP(2,1/(Updates!$B$2:$B$100=A4),Updates!$N$2:$N$100),VLOOKUP(A4,Baseline!$A$2:$H$10,6,FALSE)) -> 0 | E4: =IFERROR(LOOKUP(2,1/(Updates!$B$2:$B$100=A4),Updates!$O$2:$O$100),VLOOKUP(A4,Baseline!$A$2:$H$10,7,FALSE)) -> 360 | F4: =IFERROR(LOOKUP(2,1/(Updates!$B$2:$B$100=A4),Updates!$P$2:$P$100),VLOOKUP(A4,Baseline!$A$2:$H$10,8,FALSE)) -> 600 | G4: =IFERROR(LOOKUP(2,1/((Updates!$B$2:$B$100=A4)*(Updates!$F$2:$F$100<>"Completed")*(Updates!$F$2:$F$100<>"Cancelled")*(Updates!$F$2:$F$100<>"Postponed")),Updates!$C$2:$C$100),"TBD") -> 46339 | H4: =IF(G4="TBD","TBD",IFERROR(LOOKUP(2,1/((Updates!$B$2:$B$100=A4)*(Updates!$C$2:$C$100=G4)),Updates!$D$2:$D$100),"TBD")) -> England
A5: Tina Macpherson Trophy | B5: =IFERROR(LOOKUP(2,1/(Updates!$B$2:$B$100=A5),Updates!$L$2:$L$100),VLOOKUP(A5,Baseline!$A$2:$H$10,4,FALSE)) -> Australia | C5: =IFERROR(LOOKUP(2,1/(Updates!$B$2:$B$100=A5),Updates!$M$2:$M$100),VLOOKUP(A5,Baseline!$A$2:$H$10,5,FALSE)) -> 46077 | D5: =IFERROR(LOOKUP(2,1/(Updates!$B$2:$B$100=A5),Updates!$N$2:$N$100),VLOOKUP(A5,Baseline!$A$2:$H$10,6,FALSE)) -> 8 | E5: =IFERROR(LOOKUP(2,1/(Updates!$B$2:$B$100=A5),Updates!$O$2:$O$100),VLOOKUP(A5,Baseline!$A$2:$H$10,7,FALSE)) -> 120 | F5: =IFERROR(LOOKUP(2,1/(Updates!$B$2:$B$100=A5),Updates!$P$2:$P$100),VLOOKUP(A5,Baseline!$A$2:$H$10,8,FALSE)) -> 254 | G5: =IFERROR(LOOKUP(2,1/((Updates!$B$2:$B$100=A5)*(Updates!$F$2:$F$100<>"Completed")*(Updates!$F$2:$F$100<>"Cancelled")*(Updates!$F$2:$F$100<>"Postponed")),Updates!$C$2:$C$100),"TBD") -> 46371 | H5: =IF(G5="TBD","TBD",IFERROR(LOOKUP(2,1/((Updates!$B$2:$B$100=A5)*(Updates!$C$2:$C$100=G5)),Updates!$D$2:$D$100),"TBD")) -> Sri Lanka
A6: Ricky Ponting Ribbon | B6: =IFERROR(LOOKUP(2,1/(Updates!$B$2:$B$100=A6),Updates!$L$2:$L$100),VLOOKUP(A6,Baseline!$A$2:$H$10,4,FALSE)) -> Ireland | C6: =IFERROR(LOOKUP(2,1/(Updates!$B$2:$B$100=A6),Updates!$M$2:$M$100),VLOOKUP(A6,Baseline!$A$2:$H$10,5,FALSE)) -> 46199 | D6: =IFERROR(LOOKUP(2,1/(Updates!$B$2:$B$100=A6),Updates!$N$2:$N$100),VLOOKUP(A6,Baseline!$A$2:$H$10,6,FALSE)) -> 1 | E6: =IFERROR(LOOKUP(2,1/(Updates!$B$2:$B$100=A6),Updates!$O$2:$O$100),VLOOKUP(A6,Baseline!$A$2:$H$10,7,FALSE)) -> 89 | F6: =IFERROR(LOOKUP(2,1/(Updates!$B$2:$B$100=A6),Updates!$P$2:$P$100),VLOOKUP(A6,Baseline!$A$2:$H$10,8,FALSE)) -> 152 | G6: =IFERROR(LOOKUP(2,1/((Updates!$B$2:$B$100=A6)*(Updates!$F$2:$F$100<>"Completed")*(Updates!$F$2:$F$100<>"Cancelled")*(Updates!$F$2:$F$100<>"Postponed")),Updates!$C$2:$C$100),"TBD") -> TBD | H6: =IF(G6="TBD","TBD",IFERROR(LOOKUP(2,1/((Updates!$B$2:$B$100=A6)*(Updates!$C$2:$C$100=G6)),Updates!$D$2:$D$100),"TBD")) -> TBD
A7: Rebecca Rolls Ribbon | B7: =IFERROR(LOOKUP(2,1/(Updates!$B$2:$B$100=A7),Updates!$L$2:$L$100),VLOOKUP(A7,Baseline!$A$2:$H$10,4,FALSE)) -> Australia | C7: =IFERROR(LOOKUP(2,1/(Updates!$B$2:$B$100=A7),Updates!$M$2:$M$100),VLOOKUP(A7,Baseline!$A$2:$H$10,5,FALSE)) -> 46186 | D7: =IFERROR(LOOKUP(2,1/(Updates!$B$2:$B$100=A7),Updates!$N$2:$N$100),VLOOKUP(A7,Baseline!$A$2:$H$10,6,FALSE)) -> 6 | E7: =IFERROR(LOOKUP(2,1/(Updates!$B$2:$B$100=A7),Updates!$O$2:$O$100),VLOOKUP(A7,Baseline!$A$2:$H$10,7,FALSE)) -> 76 | F7: =IFERROR(LOOKUP(2,1/(Updates!$B$2:$B$100=A7),Updates!$P$2:$P$100),VLOOKUP(A7,Baseline!$A$2:$H$10,8,FALSE)) -> 139 | G7: =IFERROR(LOOKUP(2,1/((Updates!$B$2:$B$100=A7)*(Updates!$F$2:$F$100<>"Completed")*(Updates!$F$2:$F$100<>"Cancelled")*(Updates!$F$2:$F$100<>"Postponed")),Updates!$C$2:$C$100),"TBD") -> 46313 | H7: =IF(G7="TBD","TBD",IFERROR(LOOKUP(2,1/((Updates!$B$2:$B$100=A7)*(Updates!$C$2:$C$100=G7)),Updates!$D$2:$D$100),"TBD")) -> New Zealand
A8: Yusuf Pathan Plate | B8: =IFERROR(LOOKUP(2,1/(Updates!$B$2:$B$100=A8),Updates!$L$2:$L$100),VLOOKUP(A8,Baseline!$A$2:$H$10,4,FALSE)) -> Royal Challengers Bengaluru | C8: =IFERROR(LOOKUP(2,1/(Updates!$B$2:$B$100=A8),Updates!$M$2:$M$100),VLOOKUP(A8,Baseline!$A$2:$H$10,5,FALSE)) -> 46173 | D8: =IFERROR(LOOKUP(2,1/(Updates!$B$2:$B$100=A8),Updates!$N$2:$N$100),VLOOKUP(A8,Baseline!$A$2:$H$10,6,FALSE)) -> 0 | E8: =IFERROR(LOOKUP(2,1/(Updates!$B$2:$B$100=A8),Updates!$O$2:$O$100),VLOOKUP(A8,Baseline!$A$2:$H$10,7,FALSE)) -> 150 | F8: =IFERROR(LOOKUP(2,1/(Updates!$B$2:$B$100=A8),Updates!$P$2:$P$100),VLOOKUP(A8,Baseline!$A$2:$H$10,8,FALSE)) -> 125 | G8: =IFERROR(LOOKUP(2,1/((Updates!$B$2:$B$100=A8)*(Updates!$F$2:$F$100<>"Completed")*(Updates!$F$2:$F$100<>"Cancelled")*(Updates!$F$2:$F$100<>"Postponed")),Updates!$C$2:$C$100),"TBD") -> TBD | H8: =IF(G8="TBD","TBD",IFERROR(LOOKUP(2,1/((Updates!$B$2:$B$100=A8)*(Updates!$C$2:$C$100=G8)),Updates!$D$2:$D$100),"TBD")) -> TBD
A9: Uwe Seeler Trophy | B9: =IFERROR(LOOKUP(2,1/(Updates!$B$2:$B$100=A9),Updates!$L$2:$L$100),VLOOKUP(A9,Baseline!$A$2:$H$10,4,FALSE)) -> Bayern München | C9: =IFERROR(LOOKUP(2,1/(Updates!$B$2:$B$100=A9),Updates!$M$2:$M$100),VLOOKUP(A9,Baseline!$A$2:$H$10,5,FALSE)) -> 46081 | D9: =IFERROR(LOOKUP(2,1/(Updates!$B$2:$B$100=A9),Updates!$N$2:$N$100),VLOOKUP(A9,Baseline!$A$2:$H$10,6,FALSE)) -> 11 | E9: =IFERROR(LOOKUP(2,1/(Updates!$B$2:$B$100=A9),Updates!$O$2:$O$100),VLOOKUP(A9,Baseline!$A$2:$H$10,7,FALSE)) -> 681 | F9: =IFERROR(LOOKUP(2,1/(Updates!$B$2:$B$100=A9),Updates!$P$2:$P$100),VLOOKUP(A9,Baseline!$A$2:$H$10,8,FALSE)) -> 1443 | G9: =IFERROR(LOOKUP(2,1/((Updates!$B$2:$B$100=A9)*(Updates!$F$2:$F$100<>"Completed")*(Updates!$F$2:$F$100<>"Cancelled")*(Updates!$F$2:$F$100<>"Postponed")),Updates!$C$2:$C$100),"TBD") -> 46269 | H9: =IF(G9="TBD","TBD",IFERROR(LOOKUP(2,1/((Updates!$B$2:$B$100=A9)*(Updates!$C$2:$C$100=G9)),Updates!$D$2:$D$100),"TBD")) -> Schalke FC
A10: Heidi Mohr Pott | B10: =IFERROR(LOOKUP(2,1/(Updates!$B$2:$B$100=A10),Updates!$L$2:$L$100),VLOOKUP(A10,Baseline!$A$2:$H$10,4,FALSE)) -> Bayern München | C10: =IFERROR(LOOKUP(2,1/(Updates!$B$2:$B$100=A10),Updates!$M$2:$M$100),VLOOKUP(A10,Baseline!$A$2:$H$10,5,FALSE)) -> 45730 | D10: =IFERROR(LOOKUP(2,1/(Updates!$B$2:$B$100=A10),Updates!$N$2:$N$100),VLOOKUP(A10,Baseline!$A$2:$H$10,6,FALSE)) -> 32 | E10: =IFERROR(LOOKUP(2,1/(Updates!$B$2:$B$100=A10),Updates!$O$2:$O$100),VLOOKUP(A10,Baseline!$A$2:$H$10,7,FALSE)) -> 113 | F10: =IFERROR(LOOKUP(2,1/(Updates!$B$2:$B$100=A10),Updates!$P$2:$P$100),VLOOKUP(A10,Baseline!$A$2:$H$10,8,FALSE)) -> 655 | G10: =IFERROR(LOOKUP(2,1/((Updates!$B$2:$B$100=A10)*(Updates!$F$2:$F$100<>"Completed")*(Updates!$F$2:$F$100<>"Cancelled")*(Updates!$F$2:$F$100<>"Postponed")),Updates!$C$2:$C$100),"TBD") -> 46265 | H10: =IF(G10="TBD","TBD",IFERROR(LOOKUP(2,1/((Updates!$B$2:$B$100=A10)*(Updates!$C$2:$C$100=G10)),Updates!$D$2:$D$100),"TBD")) -> 1. FSV Mainz 05

Sheet Website Export
A1: championship | B1: current_holder | C1: current_since | D1: current_defences | E1: transfers | F1: total_defences | G1: next_date | H1: next_opponent
A2: =Dashboard!A2 -> Charles Bannerman Belt | B2: =Dashboard!B2 -> Australia | C2: =Dashboard!C2 -> 46308 | D2: =Dashboard!D2 -> 0 | E2: =Dashboard!E2 -> 215 | F2: =Dashboard!F2 -> 404 | G2: =Dashboard!G2 -> 46313 | H2: =Dashboard!H2 -> South Africa
A3: =Dashboard!A3 -> Myrtle Maclagan Medal | B3: =Dashboard!B3 -> Australia | C3: =Dashboard!C3 -> 46089 | D3: =Dashboard!D3 -> 0 | E3: =Dashboard!E3 -> 8 | F3: =Dashboard!F3 -> 74 | G3: =Dashboard!G3 -> 46485 | H3: =Dashboard!H3 -> South Africa
A4: =Dashboard!A4 -> John Edrich Jug | B4: =Dashboard!B4 -> Australia | C4: =Dashboard!C4 -> 46295 | D4: =Dashboard!D4 -> 0 | E4: =Dashboard!E4 -> 360 | F4: =Dashboard!F4 -> 600 | G4: =Dashboard!G4 -> 46339 | H4: =Dashboard!H4 -> England
A5: =Dashboard!A5 -> Tina Macpherson Trophy | B5: =Dashboard!B5 -> Australia | C5: =Dashboard!C5 -> 46077 | D5: =Dashboard!D5 -> 8 | E5: =Dashboard!E5 -> 120 | F5: =Dashboard!F5 -> 254 | G5: =Dashboard!G5 -> 46371 | H5: =Dashboard!H5 -> Sri Lanka
A6: =Dashboard!A6 -> Ricky Ponting Ribbon | B6: =Dashboard!B6 -> Ireland | C6: =Dashboard!C6 -> 46199 | D6: =Dashboard!D6 -> 1 | E6: =Dashboard!E6 -> 89 | F6: =Dashboard!F6 -> 152 | G6: =Dashboard!G6 -> TBD | H6: =Dashboard!H6 -> TBD
A7: =Dashboard!A7 -> Rebecca Rolls Ribbon | B7: =Dashboard!B7 -> Australia | C7: =Dashboard!C7 -> 46186 | D7: =Dashboard!D7 -> 6 | E7: =Dashboard!E7 -> 76 | F7: =Dashboard!F7 -> 139 | G7: =Dashboard!G7 -> 46313 | H7: =Dashboard!H7 -> New Zealand
A8: =Dashboard!A8 -> Yusuf Pathan Plate | B8: =Dashboard!B8 -> Royal Challengers Bengaluru | C8: =Dashboard!C8 -> 46173 | D8: =Dashboard!D8 -> 0 | E8: =Dashboard!E8 -> 150 | F8: =Dashboard!F8 -> 125 | G8: =Dashboard!G8 -> TBD | H8: =Dashboard!H8 -> TBD
